Process SpawnProcess-1:
fastapi_app  | Traceback (most recent call last):
fastapi_app  |   File "/usr/local/lib/python3.11/site-packages/sqlalchemy/engine/base.py", line 146, in __init__
fastapi_app  |     self._dbapi_connection = engine.raw_connection()
fastapi_app  |                              ^^^^^^^^^^^^^^^^^^^^^^^
fastapi_app  |   File "/usr/local/lib/python3.11/site-packages/sqlalchemy/engine/base.py", line 3300, in raw_connection
fastapi_app  |     return self.pool.connect()
fastapi_app  |            ^^^^^^^^^^^^^^^^^^^
fastapi_app  |   File "/usr/local/lib/python3.11/site-packages/sqlalchemy/pool/base.py", line 449, in connect
fastapi_app  |     return _ConnectionFairy._checkout(self)
fastapi_app  |            ^^^^^^^^^^^^^^^^^^^^^^^^^^^^^^^^
fastapi_app  |   File "/usr/local/lib/python3.11/site-packages/sqlalchemy/pool/base.py", line 1263, in _checkout
fastapi_app  |     fairy = _ConnectionRecord.checkout(pool)
fastapi_app  |             ^^^^^^^^^^^^^^^^^^^^^^^^^^^^^^^^
fastapi_app  |   File "/usr/local/lib/python3.11/site-packages/sqlalchemy/pool/base.py", line 712, in checkout
fastapi_app  |     rec = pool._do_get()
fastapi_app  |           ^^^^^^^^^^^^^^
fastapi_app  |   File "/usr/local/lib/python3.11/site-packages/sqlalchemy/pool/impl.py", line 179, in _do_get
fastapi_app  |     with util.safe_reraise():
fastapi_app  |   File "/usr/local/lib/python3.11/site-packages/sqlalchemy/util/langhelpers.py", line 146, in __exit__
fastapi_app  |     raise exc_value.with_traceback(exc_tb)
fastapi_app  |   File "/usr/local/lib/python3.11/site-packages/sqlalchemy/pool/impl.py", line 177, in _do_get
fastapi_app  |     return self._create_connection()
fastapi_app  |            ^^^^^^^^^^^^^^^^^^^^^^^^^
fastapi_app  |   File "/usr/local/lib/python3.11/site-packages/sqlalchemy/pool/base.py", line 390, in _create_connection
fastapi_app  |     return _ConnectionRecord(self)
fastapi_app  |            ^^^^^^^^^^^^^^^^^^^^^^^
fastapi_app  |   File "/usr/local/lib/python3.11/site-packages/sqlalchemy/pool/base.py", line 674, in __init__
fastapi_app  |     self.__connect()
fastapi_app  |   File "/usr/local/lib/python3.11/site-packages/sqlalchemy/pool/base.py", line 900, in __connect
fastapi_app  |     with util.safe_reraise():
fastapi_app  |   File "/usr/local/lib/python3.11/site-packages/sqlalchemy/util/langhelpers.py", line 146, in __exit__
fastapi_app  |     raise exc_value.with_traceback(exc_tb)
fastapi_app  |   File "/usr/local/lib/python3.11/site-packages/sqlalchemy/pool/base.py", line 896, in __connect
fastapi_app  |     self.dbapi_connection = connection = pool._invoke_creator(self)
fastapi_app  |                                          ^^^^^^^^^^^^^^^^^^^^^^^^^^
fastapi_app  |   File "/usr/local/lib/python3.11/site-packages/sqlalchemy/engine/create.py", line 643, in connect
fastapi_app  |     return dialect.connect(*cargs, **cparams)
fastapi_app  |            ^^^^^^^^^^^^^^^^^^^^^^^^^^^^^^^^^^
fastapi_app  |   File "/usr/local/lib/python3.11/site-packages/sqlalchemy/engine/default.py", line 620, in connect
fastapi_app  |     return self.loaded_dbapi.connect(*cargs, **cparams)
fastapi_app  |            ^^^^^^^^^^^^^^^^^^^^^^^^^^^^^^^^^^^^^^^^^^^^
fastapi_app  |   File "/usr/local/lib/python3.11/site-packages/psycopg2/__init__.py", line 122, in connect
fastapi_app  |     conn = _connect(dsn, connection_factory=connection_factory, **kwasync)
fastapi_app  |            ^^^^^^^^^^^^^^^^^^^^^^^^^^^^^^^^^^^^^^^^^^^^^^^^^^^^^^^^^^^^^^^
fastapi_app  | psycopg2.OperationalError: connection to server at "db" (172.18.0.2), port 5432 failed: FATAL:  password authentication failed for user "postgresql"
fastapi_app  | 
fastapi_app  | 
fastapi_app  | The above exception was the direct cause of the following exception:
fastapi_app  | 
fastapi_app  | Traceback (most recent call last):
fastapi_app  |   File "/usr/local/lib/python3.11/multiprocessing/process.py", line 314, in _bootstrap
fastapi_app  |     self.run()
fastapi_app  |   File "/usr/local/lib/python3.11/multiprocessing/process.py", line 108, in run
fastapi_app  |     self._target(*self._args, **self._kwargs)
fastapi_app  |   File "/usr/local/lib/python3.11/site-packages/uvicorn/_subprocess.py", line 80, in subprocess_started
fastapi_app  |     target(sockets=sockets)
fastapi_app  |   File "/usr/local/lib/python3.11/site-packages/uvicorn/server.py", line 67, in run
fastapi_app  |     return asyncio.run(self.serve(sockets=sockets))
fastapi_app  |            ^^^^^^^^^^^^^^^^^^^^^^^^^^^^^^^^^^^^^^^^
fastapi_app  |   File "/usr/local/lib/python3.11/asyncio/runners.py", line 190, in run
fastapi_app  |     return runner.run(main)
fastapi_app  |            ^^^^^^^^^^^^^^^^
fastapi_app  |   File "/usr/local/lib/python3.11/asyncio/runners.py", line 118, in run
fastapi_app  |     return self._loop.run_until_complete(task)
fastapi_app  |            ^^^^^^^^^^^^^^^^^^^^^^^^^^^^^^^^^^^
fastapi_app  |   File "/usr/local/lib/python3.11/asyncio/base_events.py", line 654, in run_until_complete
fastapi_app  |     return future.result()
fastapi_app  |            ^^^^^^^^^^^^^^^
fastapi_app  |   File "/usr/local/lib/python3.11/site-packages/uvicorn/server.py", line 71, in serve
fastapi_app  |     await self._serve(sockets)
fastapi_app  |   File "/usr/local/lib/python3.11/site-packages/uvicorn/server.py", line 78, in _serve
fastapi_app  |     config.load()
fastapi_app  |   File "/usr/local/lib/python3.11/site-packages/uvicorn/config.py", line 436, in load
fastapi_app  |     self.loaded_app = import_from_string(self.app)
fastapi_app  |                       ^^^^^^^^^^^^^^^^^^^^^^^^^^^^
fastapi_app  |   File "/usr/local/lib/python3.11/site-packages/uvicorn/importer.py", line 19, in import_from_string
fastapi_app  |     module = importlib.import_module(module_str)
fastapi_app  |              ^^^^^^^^^^^^^^^^^^^^^^^^^^^^^^^^^^^
fastapi_app  |   File "/usr/local/lib/python3.11/importlib/__init__.py", line 126, in import_module
fastapi_app  |     return _bootstrap._gcd_import(name[level:], package, level)
fastapi_app  |            ^^^^^^^^^^^^^^^^^^^^^^^^^^^^^^^^^^^^^^^^^^^^^^^^^^^^
fastapi_app  |   File "<frozen importlib._bootstrap>", line 1204, in _gcd_import
fastapi_app  |   File "<frozen importlib._bootstrap>", line 1176, in _find_and_load
fastapi_app  |   File "<frozen importlib._bootstrap>", line 1147, in _find_and_load_unlocked
fastapi_app  |   File "<frozen importlib._bootstrap>", line 690, in _load_unlocked
fastapi_app  |   File "<frozen importlib._bootstrap_external>", line 940, in exec_module
fastapi_app  |   File "<frozen importlib._bootstrap>", line 241, in _call_with_frames_removed
fastapi_app  |   File "/app/main.py", line 6, in <module>
fastapi_app  |     Base.metadata.create_all(bind=engine)
fastapi_app  |   File "/usr/local/lib/python3.11/site-packages/sqlalchemy/sql/schema.py", line 5857, in create_all
fastapi_app  |     bind._run_ddl_visitor(
fastapi_app  |   File "/usr/local/lib/python3.11/site-packages/sqlalchemy/engine/base.py", line 3250, in _run_ddl_visitor
fastapi_app  |     with self.begin() as conn:
fastapi_app  |   File "/usr/local/lib/python3.11/contextlib.py", line 137, in __enter__
fastapi_app  |     return next(self.gen)
fastapi_app  |            ^^^^^^^^^^^^^^
fastapi_app  |   File "/usr/local/lib/python3.11/site-packages/sqlalchemy/engine/base.py", line 3240, in begin
fastapi_app  |     with self.connect() as conn:
fastapi_app  |          ^^^^^^^^^^^^^^
fastapi_app  |   File "/usr/local/lib/python3.11/site-packages/sqlalchemy/engine/base.py", line 3276, in connect
fastapi_app  |     return self._connection_cls(self)
fastapi_app  |            ^^^^^^^^^^^^^^^^^^^^^^^^^^
fastapi_app  |   File "/usr/local/lib/python3.11/site-packages/sqlalchemy/engine/base.py", line 148, in __init__
fastapi_app  |     Connection._handle_dbapi_exception_noconnection(
fastapi_app  |   File "/usr/local/lib/python3.11/site-packages/sqlalchemy/engine/base.py", line 2440, in _handle_dbapi_exception_noconnection
fastapi_app  |     raise sqlalchemy_exception.with_traceback(exc_info[2]) from e
fastapi_app  |   File "/usr/local/lib/python3.11/site-packages/sqlalchemy/engine/base.py", line 146, in __init__
fastapi_app  |     self._dbapi_connection = engine.raw_connection()
fastapi_app  |                              ^^^^^^^^^^^^^^^^^^^^^^^
fastapi_app  |   File "/usr/local/lib/python3.11/site-packages/sqlalchemy/engine/base.py", line 3300, in raw_connection
fastapi_app  |     return self.pool.connect()
fastapi_app  |            ^^^^^^^^^^^^^^^^^^^
fastapi_app  |   File "/usr/local/lib/python3.11/site-packages/sqlalchemy/pool/base.py", line 449, in connect
fastapi_app  |     return _ConnectionFairy._checkout(self)
fastapi_app  |            ^^^^^^^^^^^^^^^^^^^^^^^^^^^^^^^^
fastapi_app  |   File "/usr/local/lib/python3.11/site-packages/sqlalchemy/pool/base.py", line 1263, in _checkout
fastapi_app  |     fairy = _ConnectionRecord.checkout(pool)
fastapi_app  |             ^^^^^^^^^^^^^^^^^^^^^^^^^^^^^^^^
fastapi_app  |   File "/usr/local/lib/python3.11/site-packages/sqlalchemy/pool/base.py", line 712, in checkout
fastapi_app  |     rec = pool._do_get()
fastapi_app  |           ^^^^^^^^^^^^^^
fastapi_app  |   File "/usr/local/lib/python3.11/site-packages/sqlalchemy/pool/impl.py", line 179, in _do_get
fastapi_app  |     with util.safe_reraise():
fastapi_app  |   File "/usr/local/lib/python3.11/site-packages/sqlalchemy/util/langhelpers.py", line 146, in __exit__
fastapi_app  |     raise exc_value.with_traceback(exc_tb)
fastapi_app  |   File "/usr/local/lib/python3.11/site-packages/sqlalchemy/pool/impl.py", line 177, in _do_get
fastapi_app  |     return self._create_connection()
fastapi_app  |            ^^^^^^^^^^^^^^^^^^^^^^^^^
fastapi_app  |   File "/usr/local/lib/python3.11/site-packages/sqlalchemy/pool/base.py", line 390, in _create_connection
fastapi_app  |     return _ConnectionRecord(self)
fastapi_app  |            ^^^^^^^^^^^^^^^^^^^^^^^
fastapi_app  |   File "/usr/local/lib/python3.11/site-packages/sqlalchemy/pool/base.py", line 674, in __init__
fastapi_app  |     self.__connect()
fastapi_app  |   File "/usr/local/lib/python3.11/site-packages/sqlalchemy/pool/base.py", line 900, in __connect
fastapi_app  |     with util.safe_reraise():
fastapi_app  |   File "/usr/local/lib/python3.11/site-packages/sqlalchemy/util/langhelpers.py", line 146, in __exit__
fastapi_app  |     raise exc_value.with_traceback(exc_tb)
fastapi_app  |   File "/usr/local/lib/python3.11/site-packages/sqlalchemy/pool/base.py", line 896, in __connect
fastapi_app  |     self.dbapi_connection = connection = pool._invoke_creator(self)
fastapi_app  |                                          ^^^^^^^^^^^^^^^^^^^^^^^^^^
fastapi_app  |   File "/usr/local/lib/python3.11/site-packages/sqlalchemy/engine/create.py", line 643, in connect
fastapi_app  |     return dialect.connect(*cargs, **cparams)
fastapi_app  |            ^^^^^^^^^^^^^^^^^^^^^^^^^^^^^^^^^^
fastapi_app  |   File "/usr/local/lib/python3.11/site-packages/sqlalchemy/engine/default.py", line 620, in connect
fastapi_app  |     return self.loaded_dbapi.connect(*cargs, **cparams)
fastapi_app  |            ^^^^^^^^^^^^^^^^^^^^^^^^^^^^^^^^^^^^^^^^^^^^
fastapi_app  |   File "/usr/local/lib/python3.11/site-packages/psycopg2/__init__.py", line 122, in connect
fastapi_app  |     conn = _connect(dsn, connection_factory=connection_factory, **kwasync)
fastapi_app  |            ^^^^^^^^^^^^^^^^^^^^^^^^^^^^^^^^^^^^^^^^^^^^^^^^^^^^^^^^^^^^^^^
fastapi_app  | sqlalchemy.exc.OperationalError: (psycopg2.OperationalError) connection to server at "db" (172.18.0.2), port 5432 failed: FATAL:  password authentication failed for user "postgresql"
fastapi_app  | 